
## üö® COMPLETE ERROR LOGS

### ModelManagerAgent Initial Syntax Error:
```
Traceback (most recent call last):
  File "/usr/local/lib/python3.10/runpy.py", line 187, in _run_module_as_main
    mod_name, mod_spec, code = _get_module_details(mod_name, _Error)
  File "/usr/local/lib/python3.10/runpy.py", line 157, in _get_module_details
    code = loader.get_code(mod_name)
  File "<frozen importlib._bootstrap_external>", line 1017, in get_code
  File "<frozen importlib._bootstrap_external>", line 947, in source_to_code
  File "<frozen importlib._bootstrap>", line 241, in _call_with_frames_removed
  File "/app/main_pc_code/agents/model_manager_agent.py", line 4822
    print(f"An unexpected error occurred in {agent.name if agent else 'agent'}: {e}")
IndentationError: unexpected indent
```

### ModelManagerAgent After Fix (Missing Dependencies):
```
!!! MMA SCRIPT (CODE_VERSION_IMPROVED_MMA_001) IS STARTING EXECUTION !!!
!!! MMA VERSION: IMPROVED_MMA_001 - WITH TYPE HINTS, ERROR HANDLING, AND VERSION TRACKING !!!
Traceback (most recent call last):
  File "/usr/local/lib/python3.10/runpy.py", line 196, in _run_module_as_main
    return _run_code(code, main_globals, None,
  File "/usr/local/lib/python3.10/runpy.py", line 86, in _run_code
    exec(code, run_globals)
  File "/app/main_pc_code/agents/model_manager_agent.py", line 49, in <module>
    import torch
ModuleNotFoundError: No module named 'torch'
```

### ModelManagerSuite Port Binding Errors:
```
# Error with port 8721:
zmq.error.ZMQError: Address already in use (addr='tcp://*:8721')

# Error with port 8881:
zmq.error.ZMQError: Address already in use (addr='tcp://*:8881')

# Error with port 9902 (despite port being free):
Traceback (most recent call last):
  File "/usr/local/lib/python3.10/runpy.py", line 196, in _run_module_as_main
    return _run_code(code, main_globals, None,
  File "/usr/local/lib/python3.10/runpy.py", line 86, in _run_code
    exec(code, run_globals)
  File "/app/main_pc_code/model_manager_suite.py", line 1552, in <module>
    service = ModelManagerSuite(port=args.port, health_port=args.health_port)
  File "/app/main_pc_code/model_manager_suite.py", line 333, in __init__
    self._init_zmq()
  File "/app/main_pc_code/model_manager_suite.py", line 544, in _init_zmq
    self.health_socket.bind(f"tcp://*:{self.health_check_port}")
  File "/usr/local/lib/python3.10/site-packages/zmq/sugar/socket.py", line 311, in bind
    super().bind(addr)
  File "_zmq.py", line 898, in zmq.backend.cython._zmq.Socket.bind
  File "_zmq.py", line 160, in zmq.backend.cython._zmq._check_rc
zmq.error.ZMQError: Address already in use (addr='tcp://*:9902')
```

### ModelManagerSuite Successful Binding (But Non-Responsive):
```
2025-08-02 10:50:16,222 - common.core.base_agent - WARNING - Error closing existing health socket: 'function' object has no attribute 'close'
2025-08-02 10:50:16,223 - common.core.base_agent - INFO - ModelManagerSuite successfully bound to ports 9901 and 9902
2025-08-02 10:50:16,224 - common.core.base_agent - INFO - Started HTTP health server on port 9903 (ZMQ health on 9902)
2025-08-02 10:50:18,225 - common.error_bus.nats_error_bus - ERROR - NATS Error: 
2025-08-02 10:50:19,730 - common.health.standardized_health - ERROR - Redis connection failed for ModelManagerSuite: Error -5 connecting to redis_memory:6379. No address associated with hostname.
2025-08-02 10:50:19,731 - common.core.base_agent - INFO - ‚úÖ ModelManagerSuite marked as ready in Redis
2025-08-02 10:50:20,133 - common.core.base_agent - WARNING - Timeout waiting for response from SystemDigitalTwin (attempt 1/3)
2025-08-02 10:50:21,131 - common.error_bus.nats_error_bus - ERROR - NATS Error: 
2025-08-02 10:50:25,137 - common.error_bus.nats_error_bus - ERROR - NATS Error: 
2025-08-02 10:50:27,139 - common.core.base_agent - WARNING - Timeout waiting for response from SystemDigitalTwin (attempt 2/3)
```

### ZMQ Smoke Test Failures:
```
# MMS Smoke Test Result:
python3 utils/mms_smoke_test.py
üöÄ Starting ModelManagerSuite smoke test...
‚úÖ Connected to ModelManagerSuite test instance on port 9901

üîç Testing health_check...
‚ùå ZMQ Error: Resource temporarily unavailable

# Simple ZMQ Test Result:
python3 utils/simple_zmq_test.py
Connecting to port 9901...
Sending simple message...
Waiting for response...
Error: Resource temporarily unavailable
```

### Network Diagnostics:
```
# Port check shows NO listening process despite container claims:
netstat -tlnp | grep :9901
# Result: Port 9901 not in listening state

# Container status shows running:
docker ps --format "table {{.Names}}\t{{.Status}}" | grep suite
# Result: model_manager_suite_test    Up 17 seconds
```

---

## üîß DEBUGGING ANALYSIS

**CRITICAL BLOCKER:** ModelManagerSuite must properly handle ZMQ requests on port 9901 before migration can continue.

**Debugging Steps Needed:**
1. Investigate why MMS container logs successful binding but doesn't respond to ZMQ requests
2. Check if MMS application enters proper request handling loop
3. Verify Docker port mapping functionality
4. Test MMS in standalone mode outside Docker

**Migration Status:** **SUSPENDED** until ZMQ connectivity issue resolved.
